Traceback (most recent call last):
  File "/Users/kvarada/miniforge3/envs/jbook/lib/python3.12/site-packages/jupyter_cache/executors/utils.py", line 58, in single_nb_execution
    executenb(
  File "/Users/kvarada/miniforge3/envs/jbook/lib/python3.12/site-packages/nbclient/client.py", line 1314, in execute
    return NotebookClient(nb=nb, resources=resources, km=km, **kwargs).execute()
           ^^^^^^^^^^^^^^^^^^^^^^^^^^^^^^^^^^^^^^^^^^^^^^^^^^^^^^^^^^^^^^^^^^^^^
  File "/Users/kvarada/miniforge3/envs/jbook/lib/python3.12/site-packages/jupyter_core/utils/__init__.py", line 165, in wrapped
    return loop.run_until_complete(inner)
           ^^^^^^^^^^^^^^^^^^^^^^^^^^^^^^
  File "/Users/kvarada/miniforge3/envs/jbook/lib/python3.12/asyncio/base_events.py", line 687, in run_until_complete
    return future.result()
           ^^^^^^^^^^^^^^^
  File "/Users/kvarada/miniforge3/envs/jbook/lib/python3.12/site-packages/nbclient/client.py", line 709, in async_execute
    await self.async_execute_cell(
  File "/Users/kvarada/miniforge3/envs/jbook/lib/python3.12/site-packages/nbclient/client.py", line 1062, in async_execute_cell
    await self._check_raise_for_error(cell, cell_index, exec_reply)
  File "/Users/kvarada/miniforge3/envs/jbook/lib/python3.12/site-packages/nbclient/client.py", line 918, in _check_raise_for_error
    raise CellExecutionError.from_cell_and_msg(cell, exec_reply_content)
nbclient.exceptions.CellExecutionError: An error occurred while executing the following cell:
------------------
import mglearn
from sklearn.datasets import make_blobs

X, y = make_blobs(centers=3, n_samples=120, random_state=42)
X_train, X_test, y_train, y_test = train_test_split(
    X, y, test_size=0.2, random_state=123
)
mglearn.discrete_scatter(X_train[:, 0], X_train[:, 1], y_train)
plt.xlabel("Feature 0")
plt.ylabel("Feature 1")
plt.legend(["Class 0", "Class 1", "Class 2"]);
------------------


[0;31m---------------------------------------------------------------------------[0m
[0;31mNameError[0m                                 Traceback (most recent call last)
Cell [0;32mIn[1], line 5[0m
[1;32m      2[0m [38;5;28;01mfrom[39;00m [38;5;21;01msklearn[39;00m[38;5;21;01m.[39;00m[38;5;21;01mdatasets[39;00m [38;5;28;01mimport[39;00m make_blobs
[1;32m      4[0m X, y [38;5;241m=[39m make_blobs(centers[38;5;241m=[39m[38;5;241m3[39m, n_samples[38;5;241m=[39m[38;5;241m120[39m, random_state[38;5;241m=[39m[38;5;241m42[39m)
[0;32m----> 5[0m X_train, X_test, y_train, y_test [38;5;241m=[39m [43mtrain_test_split[49m(
[1;32m      6[0m     X, y, test_size[38;5;241m=[39m[38;5;241m0.2[39m, random_state[38;5;241m=[39m[38;5;241m123[39m
[1;32m      7[0m )
[1;32m      8[0m mglearn[38;5;241m.[39mdiscrete_scatter(X_train[:, [38;5;241m0[39m], X_train[:, [38;5;241m1[39m], y_train)
[1;32m      9[0m plt[38;5;241m.[39mxlabel([38;5;124m"[39m[38;5;124mFeature 0[39m[38;5;124m"[39m)

[0;31mNameError[0m: name 'train_test_split' is not defined

